Workbook

Sheet How Tune-Up Pricing Works
A1: HOW TUNE-UP PRICING WORKS
A3: What a Tune-Up is
A4: The 1-day reconditioning service: we restore the finish that is already on the cabinets. Boxes, doors and drawer fronts all stay. No colour change, no style change, and it cannot be done on painted or laminate doors — those are painting or redooring jobs, priced on the other workbook.
A6: The formula
A7: Quoted price = ( Job base + Doors x Per-door rate + Drawer fronts x Per-drawer-front rate + Add-ons ) x 1.29, floored at $2,500.
A8: The 1.29 is Shop Labor 24% + Shop Overhead 5%, which go on the proposal as their own two lines, same as always in ServiceMinder.
A10: Why per door
A11: The boxes stay put, so the work scales with the number of doors and drawer fronts, not with the size of the kitchen. Count the doors, count the drawer fronts, and the job prices itself. The job base covers measure, set-up, masking and clean-up — it is why a 12-door kitchen is not half the price of a 24-door kitchen.
A13: The three tiers
A14: Tier 1 Essential — $45/door, $25/drawer front, $450 base. Deep clean and degrease, restore the existing finish, colour-match minor scratches and water marks, tighten and adjust every door and drawer.
A15: Tier 2 Enhanced — $60/door, $32/drawer front, $550 base. Everything in Tier 1, plus new knobs and pulls installed, hinge and drawer-glide adjustment or replacement, and repair of gouges, chips and worn edges.
A16: Tier 3 Elite — $75/door, $40/drawer front, $650 base. Everything in Tier 2, plus full colour-matched repair of damaged doors and face frames, toe-kick and end-panel refresh, and an accessory or organiser allowance.
... A33: The per-door, per-drawer-front and job-base rates are assumption defaults set 2026-08-18 — no per-door Tune-Up price list existed in the Drive or the repo. Confirm them against recent signed Tune-Up proposals, then change them once on the Rate Card tab.

Sheet Rate Card
A1: TUNE-UP RATE CARD — owner-set. Edit the yellow cells; every tab follows them.
A3: Per-door and per-drawer-front prices are LINE-ITEM prices. Shop Labor and Shop Overhead are added on top as their own proposal lines, exactly as in ServiceMinder.
A5: Tier | B5: Per Door | C5: Per Drawer Front | D5: Job Base | E5: Hrs / Door | F5: Hrs / Drawer Front | G5: Base Hrs | H5: Crew Rate $/hr
A6: Tier 1 — Essential | B6: 45 | C6: 25 | D6: 450 | E6: 0.3 | F6: 0.12 | G6: 4 | H6: 65
A7: Tier 2 — Enhanced | B7: 60 | C7: 32 | D7: 550 | E7: 0.38 | F7: 0.16 | G7: 5 | H7: 65
A8: Tier 3 — Elite | B8: 75 | C8: 40 | D8: 650 | E8: 0.48 | F8: 0.2 | G8: 6 | H8: 65
A10: Source: per-door, per-drawer-front, job-base and crew-hour figures are ASSUMPTION defaults set 2026-08-18 — no per-door Tune-Up price list existed in the Drive or the repo. Confirm against recent signed Tune-Up proposals before field use. Crew rate $65/hr is the internal Track A rate.
A12: SETTINGS
A13: Shop Labor % | B13: 0.24 | C13: Internal — its own proposal line
A14: Shop Overhead % | B14: 0.05 | C14: Internal — its own proposal line
A15: Job minimum ($) | B15: 2500 | C15: Owner-set 2026-08-18 — no Tune-Up quotes below this
A16: Deposit % | B16: 0.5 | C16: Collected at signing
A17: Direct labor ceiling % | B17: 0.2 | C17: Internal target — flag any job above this
A18: Drawer fronts per door (matrix est.) | B18: 0.45 | C18: Used only by the Price by Door Count tab
A20: WHAT EACH TIER INCLUDES
A21: Tier | B21: Scope
A22: Tier 1 — Essential | B22: Deep clean and degrease, restore the existing finish, colour-match minor scratches and water marks, tighten and adjust every door and drawer, re-set doors to square.
A23: Tier 2 — Enhanced | B23: Everything in Tier 1, plus new knobs and pulls installed, hinge and drawer-glide adjustment or replacement, and repair of gouges, chips and worn edges.
A24: Tier 3 — Elite | B24: Everything in Tier 2, plus full colour-matched repair of damaged doors and face frames, toe-kick and end-panel refresh, and an accessory or organiser allowance.
A26: TUNE-UP ADD-ONS
A27: Add-On | B27: Unit | C27: Rate | D27: Source
A28: Hardware — material | B28: per piece | C28: 17 | D28: KTU internal rate card, 2026-06-05
A29: Hardware — install | B29: per piece | C29: 17 | D29: KTU internal rate card, 2026-06-05
A30: Rollout trays | B30: each | C30: 275 | D30: KTU internal rate card, 2026-06-05
A31: Trash pullout | B31: each | C31: 450 | D31: KTU internal rate card, 2026-06-05
A32: Lazy Susan | B32: each | C32: 460 | D32: KTU internal rate card, 2026-06-05
A33: Undercabinet lighting | B33: per job | C33: 1150 | D33: KTU internal rate card, 2026-06-05
A34: Add crown molding | B34: per run | C34: 230 | D34: KTU internal rate card, 2026-06-05
A35: Crown transition | B35: per piece | C35: 230 | D35: KTU internal rate card, 2026-06-05
A36: Matching end panels | B36: each | C36: 192 | D36: KTU internal rate card, 2026-06-05
A37: Refrigerator panel | B37: each | C37: 345 | D37: KTU internal rate card, 2026-06-05
A38: Repair drywall and spackle | B38: per area | C38: 650 | D38: KTU internal rate card, 2026-06-05
A39: Paint kitchen trims | B39: per job | C39: 650 | D39: KTU internal rate card, 2026-06-05
... A42: Extra day on site | B42: per day | C42: 900 | D42: Assumption — confirm

Sheet Price by Door Count
A1: TUNE-UP PRICE BY DOOR COUNT — all-in, including Shop Labor, Overhead and the $2,500 minimum
A3: Drawer fronts estimated at the Rate Card ratio (default 0.45 per door). Add-ons are not included. Shaded prices are jobs where the $2,500 minimum did the pricing, not the door count.
A5: Doors | B5: Drawer fronts (est.) | C5: Tier 1 — Essential | D5: Tier 2 — Enhanced | E5: Tier 3 — Elite | F5: Tier 1 per door | G5: Tier 2 per door | H5: Tier 3 per door
A6: 8 | B6: =ROUND($A6*'Rate Card'!$B$18,0) | C6: =MAX('Rate Card'!$B$15,('Rate Card'!$D$6+$A6*'Rate Card'!$B$6+$B6*'Rate Card'!$C$6)*(1+'Rate Card'!$B$13+'Rate Card'!$B$14)) | D6: =MAX('Rate Card'!$B$15,('Rate Card'!$D$7+$A6*'Rate Card'!$B$7+$B6*'Rate Card'!$C$7)*(1+'Rate Card'!$B$13+'Rate Card'!$B$14)) | E6: =MAX('Rate Card'!$B$15,('Rate Card'!$D$8+$A6*'Rate Card'!$B$8+$B6*'Rate Card'!$C$8)*(1+'Rate Card'!$B$13+'Rate Card'!$B$14)) | F6: =C6/$A6 | G6: =D6/$A6 | H6: =E6/$A6
A7: 10 | B7: =ROUND($A7*'Rate Card'!$B$18,0) | C7: =MAX('Rate Card'!$B$15,('Rate Card'!$D$6+$A7*'Rate Card'!$B$6+$B7*'Rate Card'!$C$6)*(1+'Rate Card'!$B$13+'Rate Card'!$B$14)) | D7: =MAX('Rate Card'!$B$15,('Rate Card'!$D$7+$A7*'Rate Card'!$B$7+$B7*'Rate Card'!$C$7)*(1+'Rate Card'!$B$13+'Rate Card'!$B$14)) | E7: =MAX('Rate Card'!$B$15,('Rate Card'!$D$8+$A7*'Rate Card'!$B$8+$B7*'Rate Card'!$C$8)*(1+'Rate Card'!$B$13+'Rate Card'!$B$14)) | F7: =C7/$A7 | G7: =D7/$A7 | H7: =E7/$A7
A8: 12 | B8: =ROUND($A8*'Rate Card'!$B$18,0) | C8: =MAX('Rate Card'!$B$15,('Rate Card'!$D$6+$A8*'Rate Card'!$B$6+$B8*'Rate Card'!$C$6)*(1+'Rate Card'!$B$13+'Rate Card'!$B$14)) | D8: =MAX('Rate Card'!$B$15,('Rate Card'!$D$7+$A8*'Rate Card'!$B$7+$B8*'Rate Card'!$C$7)*(1+'Rate Card'!$B$13+'Rate Card'!$B$14)) | E8: =MAX('Rate Card'!$B$15,('Rate Card'!$D$8+$A8*'Rate Card'!$B$8+$B8*'Rate Card'!$C$8)*(1+'Rate Card'!$B$13+'Rate Card'!$B$14)) | F8: =C8/$A8 | G8: =D8/$A8 | H8: =E8/$A8
A9: 14 | B9: =ROUND($A9*'Rate Card'!$B$18,0) | C9: =MAX('Rate Card'!$B$15,('Rate Card'!$D$6+$A9*'Rate Card'!$B$6+$B9*'Rate Card'!$C$6)*(1+'Rate Card'!$B$13+'Rate Card'!$B$14)) | D9: =MAX('Rate Card'!$B$15,('Rate Card'!$D$7+$A9*'Rate Card'!$B$7+$B9*'Rate Card'!$C$7)*(1+'Rate Card'!$B$13+'Rate Card'!$B$14)) | E9: =MAX('Rate Card'!$B$15,('Rate Card'!$D$8+$A9*'Rate Card'!$B$8+$B9*'Rate Card'!$C$8)*(1+'Rate Card'!$B$13+'Rate Card'!$B$14)) | F9: =C9/$A9 | G9: =D9/$A9 | H9: =E9/$A9
A10: 16 | B10: =ROUND($A10*'Rate Card'!$B$18,0) | C10: =MAX('Rate Card'!$B$15,('Rate Card'!$D$6+$A10*'Rate Card'!$B$6+$B10*'Rate Card'!$C$6)*(1+'Rate Card'!$B$13+'Rate Card'!$B$14)) | D10: =MAX('Rate Card'!$B$15,('Rate Card'!$D$7+$A10*'Rate Card'!$B$7+$B10*'Rate Card'!$C$7)*(1+'Rate Card'!$B$13+'Rate Card'!$B$14)) | E10: =MAX('Rate Card'!$B$15,('Rate Card'!$D$8+$A10*'Rate Card'!$B$8+$B10*'Rate Card'!$C$8)*(1+'Rate Card'!$B$13+'Rate Card'!$B$14)) | F10: =C10/$A10 | G10: =D10/$A10 | H10: =E10/$A10
A11: 18 | B11: =ROUND($A11*'Rate Card'!$B$18,0) | C11: =MAX('Rate Card'!$B$15,('Rate Card'!$D$6+$A11*'Rate Card'!$B$6+$B11*'Rate Card'!$C$6)*(1+'Rate Card'!$B$13+'Rate Card'!$B$14)) | D11: =MAX('Rate Card'!$B$15,('Rate Card'!$D$7+$A11*'Rate Card'!$B$7+$B11*'Rate Card'!$C$7)*(1+'Rate Card'!$B$13+'Rate Card'!$B$14)) | E11: =MAX('Rate Card'!$B$15,('Rate Card'!$D$8+$A11*'Rate Card'!$B$8+$B11*'Rate Card'!$C$8)*(1+'Rate Card'!$B$13+'Rate Card'!$B$14)) | F11: =C11/$A11 | G11: =D11/$A11 | H11: =E11/$A11
A12: 20 | B12: =ROUND($A12*'Rate Card'!$B$18,0) | C12: =MAX('Rate Card'!$B$15,('Rate Card'!$D$6+$A12*'Rate Card'!$B$6+$B12*'Rate Card'!$C$6)*(1+'Rate Card'!$B$13+'Rate Card'!$B$14)) | D12: =MAX('Rate Card'!$B$15,('Rate Card'!$D$7+$A12*'Rate Card'!$B$7+$B12*'Rate Card'!$C$7)*(1+'Rate Card'!$B$13+'Rate Card'!$B$14)) | E12: =MAX('Rate Card'!$B$15,('Rate Card'!$D$8+$A12*'Rate Card'!$B$8+$B12*'Rate Card'!$C$8)*(1+'Rate Card'!$B$13+'Rate Card'!$B$14)) | F12: =C12/$A12 | G12: =D12/$A12 | H12: =E12/$A12
A13: 22 | B13: =ROUND($A13*'Rate Card'!$B$18,0) | C13: =MAX('Rate Card'!$B$15,('Rate Card'!$D$6+$A13*'Rate Card'!$B$6+$B13*'Rate Card'!$C$6)*(1+'Rate Card'!$B$13+'Rate Card'!$B$14)) | D13: =MAX('Rate Card'!$B$15,('Rate Card'!$D$7+$A13*'Rate Card'!$B$7+$B13*'Rate Card'!$C$7)*(1+'Rate Card'!$B$13+'Rate Card'!$B$14)) | E13: =MAX('Rate Card'!$B$15,('Rate Card'!$D$8+$A13*'Rate Card'!$B$8+$B13*'Rate Card'!$C$8)*(1+'Rate Card'!$B$13+'Rate Card'!$B$14)) | F13: =C13/$A13 | G13: =D13/$A13 | H13: =E13/$A13
A14: 24 | B14: =ROUND($A14*'Rate Card'!$B$18,0) | C14: =MAX('Rate Card'!$B$15,('Rate Card'!$D$6+$A14*'Rate Card'!$B$6+$B14*'Rate Card'!$C$6)*(1+'Rate Card'!$B$13+'Rate Card'!$B$14)) | D14: =MAX('Rate Card'!$B$15,('Rate Card'!$D$7+$A14*'Rate Card'!$B$7+$B14*'Rate Card'!$C$7)*(1+'Rate Card'!$B$13+'Rate Card'!$B$14)) | E14: =MAX('Rate Card'!$B$15,('Rate Card'!$D$8+$A14*'Rate Card'!$B$8+$B14*'Rate Card'!$C$8)*(1+'Rate Card'!$B$13+'Rate Card'!$B$14)) | F14: =C14/$A14 | G14: =D14/$A14 | H14: =E14/$A14
A15: 26 | B15: =ROUND($A15*'Rate Card'!$B$18,0) | C15: =MAX('Rate Card'!$B$15,('Rate Card'!$D$6+$A15*'Rate Card'!$B$6+$B15*'Rate Card'!$C$6)*(1+'Rate Card'!$B$13+'Rate Card'!$B$14)) | D15: =MAX('Rate Card'!$B$15,('Rate Card'!$D$7+$A15*'Rate Card'!$B$7+$B15*'Rate Card'!$C$7)*(1+'Rate Card'!$B$13+'Rate Card'!$B$14)) | E15: =MAX('Rate Card'!$B$15,('Rate Card'!$D$8+$A15*'Rate Card'!$B$8+$B15*'Rate Card'!$C$8)*(1+'Rate Card'!$B$13+'Rate Card'!$B$14)) | F15: =C15/$A15 | G15: =D15/$A15 | H15: =E15/$A15
A16: 28 | B16: =ROUND($A16*'Rate Card'!$B$18,0) | C16: =MAX('Rate Card'!$B$15,('Rate Card'!$D$6+$A16*'Rate Card'!$B$6+$B16*'Rate Card'!$C$6)*(1+'Rate Card'!$B$13+'Rate Card'!$B$14)) | D16: =MAX('Rate Card'!$B$15,('Rate Card'!$D$7+$A16*'Rate Card'!$B$7+$B16*'Rate Card'!$C$7)*(1+'Rate Card'!$B$13+'Rate Card'!$B$14)) | E16: =MAX('Rate Card'!$B$15,('Rate Card'!$D$8+$A16*'Rate Card'!$B$8+$B16*'Rate Card'!$C$8)*(1+'Rate Card'!$B$13+'Rate Card'!$B$14)) | F16: =C16/$A16 | G16: =D16/$A16 | H16: =E16/$A16
A17: 30 | B17: =ROUND($A17*'Rate Card'!$B$18,0) | C17: =MAX('Rate Card'!$B$15,('Rate Card'!$D$6+$A17*'Rate Card'!$B$6+$B17*'Rate Card'!$C$6)*(1+'Rate Card'!$B$13+'Rate Card'!$B$14)) | D17: =MAX('Rate Card'!$B$15,('Rate Card'!$D$7+$A17*'Rate Card'!$B$7+$B17*'Rate Card'!$C$7)*(1+'Rate Card'!$B$13+'Rate Card'!$B$14)) | E17: =MAX('Rate Card'!$B$15,('Rate Card'!$D$8+$A17*'Rate Card'!$B$8+$B17*'Rate Card'!$C$8)*(1+'Rate Card'!$B$13+'Rate Card'!$B$14)) | F17: =C17/$A17 | G17: =D17/$A17 | H17: =E17/$A17
... A32: 60 | B32: =ROUND($A32*'Rate Card'!$B$18,0) | C32: =MAX('Rate Card'!$B$15,('Rate Card'!$D$6+$A32*'Rate Card'!$B$6+$B32*'Rate Card'!$C$6)*(1+'Rate Card'!$B$13+'Rate Card'!$B$14)) | D32: =MAX('Rate Card'!$B$15,('Rate Card'!$D$7+$A32*'Rate Card'!$B$7+$B32*'Rate Card'!$C$7)*(1+'Rate Card'!$B$13+'Rate Card'!$B$14)) | E32: =MAX('Rate Card'!$B$15,('Rate Card'!$D$8+$A32*'Rate Card'!$B$8+$B32*'Rate Card'!$C$8)*(1+'Rate Card'!$B$13+'Rate Card'!$B$14)) | F32: =C32/$A32 | G32: =D32/$A32 | H32: =E32/$A32
A34: Shaded = the $2,500 minimum set the price. Below those door counts, quote $2,500 and trade the customer up with hardware, rollouts or lighting.

Sheet Quick Quote
A1: TUNE-UP QUICK QUOTE — fill in the yellow cells only
A3: Blue text = you type it. Black = calculated. Green = pulled from the Rate Card.
A5: JOB INFO
A6: Customer | B6: Example: Smith, 14 Maple Ave
A7: Date | B7: 2026-08-18
A8: Sales rep | B8: Example: Ben
A10: SCOPE
A11: Tier | B11: Tier 2 — Enhanced | C11: ← pick from the dropdown
A12: Door count | B12: 28 | C12: Every hinged door, including pantry and appliance-panel doors.
A13: Drawer front count | B13: 12 | C13: Every drawer front and false front.
A15: TUNE-UP WORK
A16: Line | B16: Qty | C16: Rate | D16: Amount
A17: Job base (measure, set-up, masking, clean-up) | B17: 1 | C17: =INDEX('Rate Card'!$D$6:$D$8,MATCH($B$11,'Rate Card'!$A$6:$A$8,0)) | D17: =B17*C17
A18: Doors | B18: =$B$12 | C18: =INDEX('Rate Card'!$B$6:$B$8,MATCH($B$11,'Rate Card'!$A$6:$A$8,0)) | D18: =B18*C18
A19: Drawer fronts | B19: =$B$13 | C19: =INDEX('Rate Card'!$C$6:$C$8,MATCH($B$11,'Rate Card'!$A$6:$A$8,0)) | D19: =B19*C19
A20: Tune-Up subtotal | D20: =SUM(D17:D19)
A22: ADD-ONS — enter a quantity for anything the job includes
A23: Add-On | B23: Qty | C23: Unit | D23: Rate | E23: Amount
A24: ='Rate Card'!A28 | B24: 0 | C24: ='Rate Card'!B28 | D24: ='Rate Card'!C28 | E24: =B24*D24
A25: ='Rate Card'!A29 | B25: 0 | C25: ='Rate Card'!B29 | D25: ='Rate Card'!C29 | E25: =B25*D25
A26: ='Rate Card'!A30 | B26: 0 | C26: ='Rate Card'!B30 | D26: ='Rate Card'!C30 | E26: =B26*D26
A27: ='Rate Card'!A31 | B27: 0 | C27: ='Rate Card'!B31 | D27: ='Rate Card'!C31 | E27: =B27*D27
A28: ='Rate Card'!A32 | B28: 0 | C28: ='Rate Card'!B32 | D28: ='Rate Card'!C32 | E28: =B28*D28
A29: ='Rate Card'!A33 | B29: 0 | C29: ='Rate Card'!B33 | D29: ='Rate Card'!C33 | E29: =B29*D29
A30: ='Rate Card'!A34 | B30: 0 | C30: ='Rate Card'!B34 | D30: ='Rate Card'!C34 | E30: =B30*D30
A31: ='Rate Card'!A35 | B31: 0 | C31: ='Rate Card'!B35 | D31: ='Rate Card'!C35 | E31: =B31*D31
A32: ='Rate Card'!A36 | B32: 0 | C32: ='Rate Card'!B36 | D32: ='Rate Card'!C36 | E32: =B32*D32
A33: ='Rate Card'!A37 | B33: 0 | C33: ='Rate Card'!B37 | D33: ='Rate Card'!C37 | E33: =B33*D33
A34: ='Rate Card'!A38 | B34: 0 | C34: ='Rate Card'!B38 | D34: ='Rate Card'!C38 | E34: =B34*D34
A35: ='Rate Card'!A39 | B35: 0 | C35: ='Rate Card'!B39 | D35: ='Rate Card'!C39 | E35: =B35*D35
... A38: ='Rate Card'!A42 | B38: 0 | C38: ='Rate Card'!B42 | D38: ='Rate Card'!C42 | E38: =B38*D38
A39: Add-ons subtotal | E39: =SUM(E24:E38)
A41: PRICE BUILD-UP
A42: Line-item subtotal | D42: =$D$20+$E$39
A43: Shop Labor | D43: =D42*'Rate Card'!$B$13
A44: Shop Overhead | D44: =D42*'Rate Card'!$B$14
A45: Price before minimum | D45: =SUM(D42:D44)
A46: Job minimum | D46: ='Rate Card'!$B$15
A47: Discount (enter as a positive $) | D47: 0
A48: QUOTED PRICE | D48: =MAX(D45-D47,D46) | E48: =IF($D$48<=D46,"MINIMUM APPLIED — this job priced up to the $2,500 floor. Trade up: hardware, rollouts, lighting.","")
...
