Workbook

Sheet How Pricing Works
A1: HOW KTU TUNE-UP PRICING WORKS
A3: The formula
A4: Quoted price = ( Job base + Doors x Door rate + Drawer fronts x Drawer-front rate + Add-ons ) x 1.29, floored at the $2,500 job minimum.
A5: The 1.29 is Shop Labor 24% + Shop Overhead 5%, which go on the proposal as their own two lines exactly as they do in ServiceMinder.
A7: Why door count
A8: On every tune-up service the cabinet boxes stay put, so the work — and the material — scales with the number of doors and drawer fronts, not with the square footage of the kitchen. Count the doors and the drawer fronts and the job prices itself.
A10: The five services
A11: Tune-Up / Reconditioning — restore the existing finish. 1-2 days. No color or style change; not for painted or laminate doors.
A12: Cabinet Painting — doors and fronts sprayed off-site, boxes and face frames done on-site. About 5 days.
A13: Redooring — new doors and drawer fronts, existing boxes and existing box finish stay. 1-2 days on site.
A14: Refacing — new doors and drawer fronts plus matching veneer over the boxes. 2-4 days on site.
A15: Reface Plus — refacing plus new panels, fillers and trim so the boxes read as new cabinetry.
... A36: The per-door, per-drawer-front and job-base rates are ASSUMPTION defaults set on 2026-08-18 — no per-door price list existed in the Drive or in the repo. Confirm them against a few recent signed reface and redoor proposals before the rep quotes live work.

Sheet Rate Card
A1: RATE CARD — edit the yellow cells to change every price in this workbook
A3: Per-door / per-drawer-front rates. These are LINE-ITEM prices; Shop Labor and Shop Overhead are added on top (see Settings below).
A5: Service | B5: Job Base | C5: L1 Door | D5: L1 Drawer Front | E5: L2 Door | F5: L2 Drawer Front | G5: L3 Door | H5: L3 Drawer Front | I5: Hrs / Door | J5: Hrs / Drawer Front | K5: Base Hrs | L5: Crew Rate $/hr
A6: Tune-Up / Reconditioning | B6: 450 | C6: 45 | D6: 25 | E6: 60 | F6: 32 | G6: 75 | H6: 40 | I6: 0.35 | J6: 0.15 | K6: 4 | L6: 65
A7: Cabinet Painting | B7: 950 | C7: 135 | D7: 75 | E7: 160 | F7: 88 | G7: 190 | H7: 105 | I7: 0.8 | J7: 0.4 | K7: 8 | L7: 65
A8: Redooring | B8: 850 | C8: 185 | D8: 95 | E8: 225 | F8: 115 | G8: 275 | H8: 140 | I8: 0.45 | J8: 0.2 | K8: 6 | L8: 65
A9: Refacing | B9: 1200 | C9: 245 | D9: 125 | E9: 295 | F9: 150 | G9: 355 | H9: 180 | I9: 0.9 | J9: 0.4 | K9: 12 | L9: 65
A10: Reface Plus | B10: 1600 | C10: 295 | D10: 150 | E10: 350 | F10: 178 | G10: 415 | H10: 210 | I10: 1.1 | J10: 0.5 | K10: 16 | L10: 65
A12: Levels: L1 = Good (thermofoil / laminate doors, standard veneer). L2 = Better (painted MDF or wood shaker). L3 = Best (premium wood species, specialty color or finish).
A13: Source: per-door, per-drawer-front, job-base and labor-hour figures are ASSUMPTION defaults set 2026-08-18 — no per-door price list existed in the Drive or the repo. Owner to confirm before field use.
A16: SETTINGS
A17: Shop Labor % | B17: 0.24 | C17: Internal — added as its own proposal line, same as ServiceMinder
A18: Shop Overhead % | B18: 0.05 | C18: Internal — added as its own proposal line
A19: Job minimum ($) | B19: 2500 | C19: Owner-set 2026-08-18: no job quotes below this
A20: Deposit % | B20: 0.5 | C20: Collected at signing
A21: Direct labor ceiling % | B21: 0.2 | C21: Internal target — flag any job above this
A22: Drawer fronts per door (matrix est.) | B22: 0.45 | C22: Used only by the Price by Door Count tab
A25: ADD-ON CATALOG
A26: Add-On | B26: Unit | C26: Rate | D26: Source
A27: New cabinet — custom/replacement | B27: per cabinet | C27: 1150 | D27: KTU internal rate card (Drive: 02 Sales & Pricing, KTU_Custom_Kitchen_Price_Adjustments, 2026-06-05)
A28: Countertops — quartz/granite | B28: per SF | C28: 105 | D28: KTU internal rate card (Drive: 02 Sales & Pricing, KTU_Custom_Kitchen_Price_Adjustments, 2026-06-05)
A29: Backsplash — quartz/granite | B29: per SF | C29: 115 | D29: KTU internal rate card (Drive: 02 Sales & Pricing, KTU_Custom_Kitchen_Price_Adjustments, 2026-06-05)
A30: Backsplash — ceramic tile | B30: per SF | C30: 96 | D30: KTU internal rate card (Drive: 02 Sales & Pricing, KTU_Custom_Kitchen_Price_Adjustments, 2026-06-05)
A31: Plank flooring install | B31: per SF | C31: 6 | D31: KTU internal rate card (Drive: 02 Sales & Pricing, KTU_Custom_Kitchen_Price_Adjustments, 2026-06-05)
A32: Existing kitchen disposal / demo | B32: per job | C32: 2300 | D32: KTU internal rate card (Drive: 02 Sales & Pricing, KTU_Custom_Kitchen_Price_Adjustments, 2026-06-05)
A33: Wall removal / entryway | B33: per opening | C33: 1535 | D33: KTU internal rate card (Drive: 02 Sales & Pricing, KTU_Custom_Kitchen_Price_Adjustments, 2026-06-05)
A34: Paint kitchen walls and ceiling | B34: per job | C34: 1920 | D34: KTU internal rate card (Drive: 02 Sales & Pricing, KTU_Custom_Kitchen_Price_Adjustments, 2026-06-05)
A35: Paint kitchen trims | B35: per job | C35: 650 | D35: KTU internal rate card (Drive: 02 Sales & Pricing, KTU_Custom_Kitchen_Price_Adjustments, 2026-06-05)
A36: Repair drywall and spackle | B36: per area | C36: 650 | D36: KTU internal rate card (Drive: 02 Sales & Pricing, KTU_Custom_Kitchen_Price_Adjustments, 2026-06-05)
A37: Reface rear of island | B37: per island | C37: 690 | D37: KTU internal rate card (Drive: 02 Sales & Pricing, KTU_Custom_Kitchen_Price_Adjustments, 2026-06-05)
A38: Refrigerator panel | B38: each | C38: 345 | D38: KTU internal rate card (Drive: 02 Sales & Pricing, KTU_Custom_Kitchen_Price_Adjustments, 2026-06-05)
... A51: Sink allowance | B51: each | C51: 275 | D51: KTU internal rate card (Drive: 02 Sales & Pricing, KTU_Custom_Kitchen_Price_Adjustments, 2026-06-05)

Sheet Quick Quote
A1: QUICK QUOTE — price a job by door count
A3: Fill in the YELLOW cells only. Everything else calculates. Blue text = you type it; black = formula.
A5: JOB INFO
A6: Customer | B6: Example: Smith, 14 Maple Ave
A7: Date | B7: 2026-08-18
A8: Sales rep | B8: Example: Rep name
A10: SCOPE
A11: Service | B11: Refacing | C11: ← pick from the dropdown
A12: Level (1 / 2 / 3) | B12: 2
A13: Door count | B13: 32 | C13: Count every hinged door, including pantry and appliance-panel doors.
A14: Drawer front count | B14: 14 | C14: Count every drawer front and false front.
A16: CABINET WORK
A17: Line | B17: Qty | C17: Rate | D17: Amount
A18: Job base (measure, delivery, set-up, clean-up) | B18: 1 | C18: =INDEX('Rate Card'!$B$6:$B$10,MATCH($B$11,'Rate Card'!$A$6:$A$10,0)) | D18: =B18*C18
A19: Doors | B19: =$B$13 | C19: =INDEX('Rate Card'!$C$6:$H$10,MATCH($B$11,'Rate Card'!$A$6:$A$10,0),$B$12*2-1) | D19: =B19*C19
A20: Drawer fronts | B20: =$B$14 | C20: =INDEX('Rate Card'!$C$6:$H$10,MATCH($B$11,'Rate Card'!$A$6:$A$10,0),$B$12*2) | D20: =B20*C20
A21: Cabinet work subtotal | D21: =SUM(D18:D20)
A23: ADD-ONS — enter a quantity next to anything the job includes
A24: Add-On | B24: Qty | C24: Unit | D24: Rate | E24: Amount
A25: ='Rate Card'!A27 | B25: 0 | C25: ='Rate Card'!B27 | D25: ='Rate Card'!C27 | E25: =B25*D25
A26: ='Rate Card'!A28 | B26: 0 | C26: ='Rate Card'!B28 | D26: ='Rate Card'!C28 | E26: =B26*D26
A27: ='Rate Card'!A29 | B27: 0 | C27: ='Rate Card'!B29 | D27: ='Rate Card'!C29 | E27: =B27*D27
A28: ='Rate Card'!A30 | B28: 0 | C28: ='Rate Card'!B30 | D28: ='Rate Card'!C30 | E28: =B28*D28
A29: ='Rate Card'!A31 | B29: 0 | C29: ='Rate Card'!B31 | D29: ='Rate Card'!C31 | E29: =B29*D29
A30: ='Rate Card'!A32 | B30: 0 | C30: ='Rate Card'!B32 | D30: ='Rate Card'!C32 | E30: =B30*D30
A31: ='Rate Card'!A33 | B31: 0 | C31: ='Rate Card'!B33 | D31: ='Rate Card'!C33 | E31: =B31*D31
A32: ='Rate Card'!A34 | B32: 0 | C32: ='Rate Card'!B34 | D32: ='Rate Card'!C34 | E32: =B32*D32
A33: ='Rate Card'!A35 | B33: 0 | C33: ='Rate Card'!B35 | D33: ='Rate Card'!C35 | E33: =B33*D33
A34: ='Rate Card'!A36 | B34: 0 | C34: ='Rate Card'!B36 | D34: ='Rate Card'!C36 | E34: =B34*D34
A35: ='Rate Card'!A37 | B35: 0 | C35: ='Rate Card'!B37 | D35: ='Rate Card'!C37 | E35: =B35*D35
A36: ='Rate Card'!A38 | B36: 0 | C36: ='Rate Card'!B38 | D36: ='Rate Card'!C38 | E36: =B36*D36
... A49: ='Rate Card'!A51 | B49: 0 | C49: ='Rate Card'!B51 | D49: ='Rate Card'!C51 | E49: =B49*D49
A50: Add-ons subtotal | E50: =SUM(E25:E49)
A52: PRICE BUILD-UP
A53: Line-item subtotal | D53: =$D$21+$E$50
A54: Shop Labor | D54: =D53*'Rate Card'!$B$17
A55: Shop Overhead | D55: =D53*'Rate Card'!$B$18
A56: Price before minimum | D56: =SUM(D53:D55)
A57: Job minimum | D57: ='Rate Card'!$B$19
A58: Discount (enter as a positive $) | D58: 0
...

Sheet Price by Door Count
A1: PRICE BY DOOR COUNT — all-in quoted price, including Shop Labor, Overhead and the job minimum
A3: Drawer fronts are estimated at the ratio on the Rate Card (default 0.45 per door). Add-ons are NOT included — add them from the Quick Quote tab. Shaded cells are jobs the minimum lifted.
A5: Doors | B5: Drawer fronts (est.) | C5: Tune-Up / Reconditioning L1 | D5: Tune-Up / Reconditioning L2 | E5: Tune-Up / Reconditioning L3 | F5: Cabinet Painting L1 | G5: Cabinet Painting L2 | H5: Cabinet Painting L3 | I5: Redooring L1 | J5: Redooring L2 | K5: Redooring L3 | L5: Refacing L1 | M5: Refacing L2 | N5: Refacing L3 | O5: Reface Plus L1 | P5: Reface Plus L2 | Q5: Reface Plus L3
A6: 8 | B6: =ROUND($A6*'Rate Card'!$B$22,0) | C6: =MAX('Rate Card'!$B$19,('Rate Card'!$B$6+$A6*'Rate Card'!$C$6+$B6*'Rate Card'!$D$6)*(1+'Rate Card'!$B$17+'Rate Card'!$B$18)) | D6: =MAX('Rate Card'!$B$19,('Rate Card'!$B$6+$A6*'Rate Card'!$E$6+$B6*'Rate Card'!$F$6)*(1+'Rate Card'!$B$17+'Rate Card'!$B$18)) | E6: =MAX('Rate Card'!$B$19,('Rate Card'!$B$6+$A6*'Rate Card'!$G$6+$B6*'Rate Card'!$H$6)*(1+'Rate Card'!$B$17+'Rate Card'!$B$18)) | F6: =MAX('Rate Card'!$B$19,('Rate Card'!$B$7+$A6*'Rate Card'!$C$7+$B6*'Rate Card'!$D$7)*(1+'Rate Card'!$B$17+'Rate Card'!$B$18)) | G6: =MAX('Rate Card'!$B$19,('Rate Card'!$B$7+$A6*'Rate Card'!$E$7+$B6*'Rate Card'!$F$7)*(1+'Rate Card'!$B$17+'Rate Card'!$B$18)) | H6: =MAX('Rate Card'!$B$19,('Rate Card'!$B$7+$A6*'Rate Card'!$G$7+$B6*'Rate Card'!$H$7)*(1+'Rate Card'!$B$17+'Rate Card'!$B$18)) | I6: =MAX('Rate Card'!$B$19,('Rate Card'!$B$8+$A6*'Rate Card'!$C$8+$B6*'Rate Card'!$D$8)*(1+'Rate Card'!$B$17+'Rate Card'!$B$18)) | J6: =MAX('Rate Card'!$B$19,('Rate Card'!$B$8+$A6*'Rate Card'!$E$8+$B6*'Rate Card'!$F$8)*(1+'Rate Card'!$B$17+'Rate Card'!$B$18)) | K6: =MAX('Rate Card'!$B$19,('Rate Card'!$B$8+$A6*'Rate Card'!$G$8+$B6*'Rate Card'!$H$8)*(1+'Rate Card'!$B$17+'Rate Card'!$B$18)) | L6: =MAX('Rate Card'!$B$19,('Rate Card'!$B$9+$A6*'Rate Card'!$C$9+$B6*'Rate Card'!$D$9)*(1+'Rate Card'!$B$17+'Rate Card'!$B$18)) | M6: =MAX('Rate Card'!$B$19,('Rate Card'!$B$9+$A6*'Rate Card'!$E$9+$B6*'Rate Card'!$F$9)*(1+'Rate Card'!$B$17+'Rate Card'!$B$18)) | N6: =MAX('Rate Card'!$B$19,('Rate Card'!$B$9+$A6*'Rate Card'!$G$9+$B6*'Rate Card'!$H$9)*(1+'Rate Card'!$B$17+'Rate Card'!$B$18)) | O6: =MAX('Rate Card'!$B$19,('Rate Card'!$B$10+$A6*'Rate Card'!$C$10+$B6*'Rate Card'!$D$10)*(1+'Rate Card'!$B$17+'Rate Card'!$B$18)) | P6: =MAX('Rate Card'!$B$19,('Rate Card'!$B$10+$A6*'Rate Card'!$E$10+$B6*'Rate Card'!$F$10)*(1+'Rate Card'!$B$17+'Rate Card'!$B$18)) | Q6: =MAX('Rate Card'!$B$19,('Rate Card'!$B$10+$A6*'Rate Card'!$G$10+$B6*'Rate Card'!$H$10)*(1+'Rate Card'!$B$17+'Rate Card'!$B$18))
A7: 10 | B7: =ROUND($A7*'Rate Card'!$B$22,0) | C7: =MAX('Rate Card'!$B$19,('Rate Card'!$B$6+$A7*'Rate Card'!$C$6+$B7*'Rate Card'!$D$6)*(1+'Rate Card'!$B$17+'Rate Card'!$B$18)) | D7: =MAX('Rate Card'!$B$19,('Rate Card'!$B$6+$A7*'Rate Card'!$E$6+$B7*'Rate Card'!$F$6)*(1+'Rate Card'!$B$17+'Rate Card'!$B$18)) | E7: =MAX('Rate Card'!$B$19,('Rate Card'!$B$6+$A7*'Rate Card'!$G$6+$B7*'Rate Card'!$H$6)*(1+'Rate Card'!$B$17+'Rate Card'!$B$18)) | F7: =MAX('Rate Card'!$B$19,('Rate Card'!$B$7+$A7*'Rate Card'!$C$7+$B7*'Rate Card'!$D$7)*(1+'Rate Card'!$B$17+'Rate Card'!$B$18)) | G7: =MAX('Rate Card'!$B$19,('Rate Card'!$B$7+$A7*'Rate Card'!$E$7+$B7*'Rate Card'!$F$7)*(1+'Rate Card'!$B$17+'Rate Card'!$B$18)) | H7: =MAX('Rate Card'!$B$19,('Rate Card'!$B$7+$A7*'Rate Card'!$G$7+$B7*'Rate Card'!$H$7)*(1+'Rate Card'!$B$17+'Rate Card'!$B$18)) | I7: =MAX('Rate Card'!$B$19,('Rate Card'!$B$8+$A7*'Rate Card'!$C$8+$B7*'Rate Card'!$D$8)*(1+'Rate Card'!$B$17+'Rate Card'!$B$18)) | J7: =MAX('Rate Card'!$B$19,('Rate Card'!$B$8+$A7*'Rate Card'!$E$8+$B7*'Rate Card'!$F$8)*(1+'Rate Card'!$B$17+'Rate Card'!$B$18)) | K7: =MAX('Rate Card'!$B$19,('Rate Card'!$B$8+$A7*'Rate Card'!$G$8+$B7*'Rate Card'!$H$8)*(1+'Rate Card'!$B$17+'Rate Card'!$B$18)) | L7: =MAX('Rate Card'!$B$19,('Rate Card'!$B$9+$A7*'Rate Card'!$C$9+$B7*'Rate Card'!$D$9)*(1+'Rate Card'!$B$17+'Rate Card'!$B$18)) | M7: =MAX('Rate Card'!$B$19,('Rate Card'!$B$9+$A7*'Rate Card'!$E$9+$B7*'Rate Card'!$F$9)*(1+'Rate Card'!$B$17+'Rate Card'!$B$18)) | N7: =MAX('Rate Card'!$B$19,('Rate Card'!$B$9+$A7*'Rate Card'!$G$9+$B7*'Rate Card'!$H$9)*(1+'Rate Card'!$B$17+'Rate Card'!$B$18)) | O7: =MAX('Rate Card'!$B$19,('Rate Card'!$B$10+$A7*'Rate Card'!$C$10+$B7*'Rate Card'!$D$10)*(1+'Rate Card'!$B$17+'Rate Card'!$B$18)) | P7: =MAX('Rate Card'!$B$19,('Rate Card'!$B$10+$A7*'Rate Card'!$E$10+$B7*'Rate Card'!$F$10)*(1+'Rate Card'!$B$17+'Rate Card'!$B$18)) | Q7: =MAX('Rate Card'!$B$19,('Rate Card'!$B$10+$A7*'Rate Card'!$G$10+$B7*'Rate Card'!$H$10)*(1+'Rate Card'!$B$17+'Rate Card'!$B$18))
A8: 12 | B8: =ROUND($A8*'Rate Card'!$B$22,0) | C8: =MAX('Rate Card'!$B$19,('Rate Card'!$B$6+$A8*'Rate Card'!$C$6+$B8*'Rate Card'!$D$6)*(1+'Rate Card'!$B$17+'Rate Card'!$B$18)) | D8: =MAX('Rate Card'!$B$19,('Rate Card'!$B$6+$A8*'Rate Card'!$E$6+$B8*'Rate Card'!$F$6)*(1+'Rate Card'!$B$17+'Rate Card'!$B$18)) | E8: =MAX('Rate Card'!$B$19,('Rate Card'!$B$6+$A8*'Rate Card'!$G$6+$B8*'Rate Card'!$H$6)*(1+'Rate Card'!$B$17+'Rate Card'!$B$18)) | F8: =MAX('Rate Card'!$B$19,('Rate Card'!$B$7+$A8*'Rate Card'!$C$7+$B8*'Rate Card'!$D$7)*(1+'Rate Card'!$B$17+'Rate Card'!$B$18)) | G8: =MAX('Rate Card'!$B$19,('Rate Card'!$B$7+$A8*'Rate Card'!$E$7+$B8*'Rate Card'!$F$7)*(1+'Rate Card'!$B$17+'Rate Card'!$B$18)) | H8: =MAX('Rate Card'!$B$19,('Rate Card'!$B$7+$A8*'Rate Card'!$G$7+$B8*'Rate Card'!$H$7)*(1+'Rate Card'!$B$17+'Rate Card'!$B$18)) | I8: =MAX('Rate Card'!$B$19,('Rate Card'!$B$8+$A8*'Rate Card'!$C$8+$B8*'Rate Card'!$D$8)*(1+'Rate Card'!$B$17+'Rate Card'!$B$18)) | J8: =MAX('Rate Card'!$B$19,('Rate Card'!$B$8+$A8*'Rate Card'!$E$8+$B8*'Rate Card'!$F$8)*(1+'Rate Card'!$B$17+'Rate Card'!$B$18)) | K8: =MAX('Rate Card'!$B$19,('Rate Card'!$B$8+$A8*'Rate Card'!$G$8+$B8*'Rate Card'!$H$8)*(1+'Rate Card'!$B$17+'Rate Card'!$B$18)) | L8: =MAX('Rate Card'!$B$19,('Rate Card'!$B$9+$A8*'Rate Card'!$C$9+$B8*'Rate Card'!$D$9)*(1+'Rate Card'!$B$17+'Rate Card'!$B$18)) | M8: =MAX('Rate Card'!$B$19,('Rate Card'!$B$9+$A8*'Rate Card'!$E$9+$B8*'Rate Card'!$F$9)*(1+'Rate Card'!$B$17+'Rate Card'!$B$18)) | N8: =MAX('Rate Card'!$B$19,('Rate Card'!$B$9+$A8*'Rate Card'!$G$9+$B8*'Rate Card'!$H$9)*(1+'Rate Card'!$B$17+'Rate Card'!$B$18)) | O8: =MAX('Rate Card'!$B$19,('Rate Card'!$B$10+$A8*'Rate Card'!$C$10+$B8*'Rate Card'!$D$10)*(1+'Rate Card'!$B$17+'Rate Card'!$B$18)) | P8: =MAX('Rate Card'!$B$19,('Rate Card'!$B$10+$A8*'Rate Card'!$E$10+$B8*'Rate Card'!$F$10)*(1+'Rate Card'!$B$17+'Rate Card'!$B$18)) | Q8: =MAX('Rate Card'!$B$19,('Rate Card'!$B$10+$A8*'Rate Card'!$G$10+$B8*'Rate Card'!$H$10)*(1+'Rate Card'!$B$17+'Rate Card'!$B$18))
A9: 14 | B9: =ROUND($A9*'Rate Card'!$B$22,0) | C9: =MAX('Rate Card'!$B$19,('Rate Card'!$B$6+$A9*'Rate Card'!$C$6+$B9*'Rate Card'!$D$6)*(1+'Rate Card'!$B$17+'Rate Card'!$B$18)) | D9: =MAX('Rate Card'!$B$19,('Rate Card'!$B$6+$A9*'Rate Card'!$E$6+$B9*'Rate Card'!$F$6)*(1+'Rate Card'!$B$17+'Rate Card'!$B$18)) | E9: =MAX('Rate Card'!$B$19,('Rate Card'!$B$6+$A9*'Rate Card'!$G$6+$B9*'Rate Card'!$H$6)*(1+'Rate Card'!$B$17+'Rate Card'!$B$18)) | F9: =MAX('Rate Card'!$B$19,('Rate Card'!$B$7+$A9*'Rate Card'!$C$7+$B9*'Rate Card'!$D$7)*(1+'Rate Card'!$B$17+'Rate Card'!$B$18)) | G9: =MAX('Rate Card'!$B$19,('Rate Card'!$B$7+$A9*'Rate Card'!$E$7+$B9*'Rate Card'!$F$7)*(1+'Rate Card'!$B$17+'Rate Card'!$B$18)) | H9: =MAX('Rate Card'!$B$19,('Rate Card'!$B$7+$A9*'Rate Card'!$G$7+$B9*'Rate Card'!$H$7)*(1+'Rate Card'!$B$17+'Rate Card'!$B$18)) | I9: =MAX('Rate Card'!$B$19,('Rate Card'!$B$8+$A9*'Rate Card'!$C$8+$B9*'Rate Card'!$D$8)*(1+'Rate Card'!$B$17+'Rate Card'!$B$18)) | J9: =MAX('Rate Card'!$B$19,('Rate Card'!$B$8+$A9*'Rate Card'!$E$8+$B9*'Rate Card'!$F$8)*(1+'Rate Card'!$B$17+'Rate Card'!$B$18)) | K9: =MAX('Rate Card'!$B$19,('Rate Card'!$B$8+$A9*'Rate Card'!$G$8+$B9*'Rate Card'!$H$8)*(1+'Rate Card'!$B$17+'Rate Card'!$B$18)) | L9: =MAX('Rate Card'!$B$19,('Rate Card'!$B$9+$A9*'Rate Card'!$C$9+$B9*'Rate Card'!$D$9)*(1+'Rate Card'!$B$17+'Rate Card'!$B$18)) | M9: =MAX('Rate Card'!$B$19,('Rate Card'!$B$9+$A9*'Rate Card'!$E$9+$B9*'Rate Card'!$F$9)*(1+'Rate Card'!$B$17+'Rate Card'!$B$18)) | N9: =MAX('Rate Card'!$B$19,('Rate Card'!$B$9+$A9*'Rate Card'!$G$9+$B9*'Rate Card'!$H$9)*(1+'Rate Card'!$B$17+'Rate Card'!$B$18)) | O9: =MAX('Rate Card'!$B$19,('Rate Card'!$B$10+$A9*'Rate Card'!$C$10+$B9*'Rate Card'!$D$10)*(1+'Rate Card'!$B$17+'Rate Card'!$B$18)) | P9: =MAX('Rate Card'!$B$19,('Rate Card'!$B$10+$A9*'Rate Card'!$E$10+$B9*'Rate Card'!$F$10)*(1+'Rate Card'!$B$17+'Rate Card'!$B$18)) | Q9: =MAX('Rate Card'!$B$19,('Rate Card'!$B$10+$A9*'Rate Card'!$G$10+$B9*'Rate Card'!$H$10)*(1+'Rate Card'!$B$17+'Rate Card'!$B$18))
A10: 16 | B10: =ROUND($A10*'Rate Card'!$B$22,0) | C10: =MAX('Rate Card'!$B$19,('Rate Card'!$B$6+$A10*'Rate Card'!$C$6+$B10*'Rate Card'!$D$6)*(1+'Rate Card'!$B$17+'Rate Card'!$B$18)) | D10: =MAX('Rate Card'!$B$19,('Rate Card'!$B$6+$A10*'Rate Card'!$E$6+$B10*'Rate Card'!$F$6)*(1+'Rate Card'!$B$17+'Rate Card'!$B$18)) | E10: =MAX('Rate Card'!$B$19,('Rate Card'!$B$6+$A10*'Rate Card'!$G$6+$B10*'Rate Card'!$H$6)*(1+'Rate Card'!$B$17+'Rate Card'!$B$18)) | F10: =MAX('Rate Card'!$B$19,('Rate Card'!$B$7+$A10*'Rate Card'!$C$7+$B10*'Rate Card'!$D$7)*(1+'Rate Card'!$B$17+'Rate Card'!$B$18)) | G10: =MAX('Rate Card'!$B$19,('Rate Card'!$B$7+$A10*'Rate Card'!$E$7+$B10*'Rate Card'!$F$7)*(1+'Rate Card'!$B$17+'Rate Card'!$B$18)) | H10: =MAX('Rate Card'!$B$19,('Rate Card'!$B$7+$A10*'Rate Card'!$G$7+$B10*'Rate Card'!$H$7)*(1+'Rate Card'!$B$17+'Rate Card'!$B$18)) | I10: =MAX('Rate Card'!$B$19,('Rate Card'!$B$8+$A10*'Rate Card'!$C$8+$B10*'Rate Card'!$D$8)*(1+'Rate Card'!$B$17+'Rate Card'!$B$18)) | J10: =MAX('Rate Card'!$B$19,('Rate Card'!$B$8+$A10*'Rate Card'!$E$8+$B10*'Rate Card'!$F$8)*(1+'Rate Card'!$B$17+'Rate Card'!$B$18)) | K10: =MAX('Rate Card'!$B$19,('Rate Card'!$B$8+$A10*'Rate Card'!$G$8+$B10*'Rate Card'!$H$8)*(1+'Rate Card'!$B$17+'Rate Card'!$B$18)) | L10: =MAX('Rate Card'!$B$19,('Rate Card'!$B$9+$A10*'Rate Card'!$C$9+$B10*'Rate Card'!$D$9)*(1+'Rate Card'!$B$17+'Rate Card'!$B$18)) | M10: =MAX('Rate Card'!$B$19,('Rate Card'!$B$9+$A10*'Rate Card'!$E$9+$B10*'Rate Card'!$F$9)*(1+'Rate Card'!$B$17+'Rate Card'!$B$18)) | N10: =MAX('Rate Card'!$B$19,('Rate Card'!$B$9+$A10*'Rate Card'!$G$9+$B10*'Rate Card'!$H$9)*(1+'Rate Card'!$B$17+'Rate Card'!$B$18)) | O10: =MAX('Rate Card'!$B$19,('Rate Card'!$B$10+$A10*'Rate Card'!$C$10+$B10*'Rate Card'!$D$10)*(1+'Rate Card'!$B$17+'Rate Card'!$B$18)) | P10: =MAX('Rate Card'!$B$19,('Rate Card'!$B$10+$A10*'Rate Card'!$E$10+$B10*'Rate Card'!$F$10)*(1+'Rate Card'!$B$17+'Rate Card'!$B$18)) | Q10: =MAX('Rate Card'!$B$19,('Rate Card'!$B$10+$A10*'Rate Card'!$G$10+$B10*'Rate Card'!$H$10)*(1+'Rate Card'!$B$17+'Rate Card'!$B$18))
A11: 18 | B11: =ROUND($A11*'Rate Card'!$B$22,0) | C11: =MAX('Rate Card'!$B$19,('Rate Card'!$B$6+$A11*'Rate Card'!$C$6+$B11*'Rate Card'!$D$6)*(1+'Rate Card'!$B$17+'Rate Card'!$B$18)) | D11: =MAX('Rate Card'!$B$19,('Rate Card'!$B$6+$A11*'Rate Card'!$E$6+$B11*'Rate Card'!$F$6)*(1+'Rate Card'!$B$17+'Rate Card'!$B$18)) | E11: =MAX('Rate Card'!$B$19,('Rate Card'!$B$6+$A11*'Rate Card'!$G$6+$B11*'Rate Card'!$H$6)*(1+'Rate Card'!$B$17+'Rate Card'!$B$18)) | F11: =MAX('Rate Card'!$B$19,('Rate Card'!$B$7+$A11*'Rate Card'!$C$7+$B11*'Rate Card'!$D$7)*(1+'Rate Card'!$B$17+'Rate Card'!$B$18)) | G11: =MAX('Rate Card'!$B$19,('Rate Card'!$B$7+$A11*'Rate Card'!$E$7+$B11*'Rate Card'!$F$7)*(1+'Rate Card'!$B$17+'Rate Card'!$B$18)) | H11: =MAX('Rate Card'!$B$19,('Rate Card'!$B$7+$A11*'Rate Card'!$G$7+$B11*'Rate Card'!$H$7)*(1+'Rate Card'!$B$17+'Rate Card'!$B$18)) | I11: =MAX('Rate Card'!$B$19,('Rate Card'!$B$8+$A11*'Rate Card'!$C$8+$B11*'Rate Card'!$D$8)*(1+'Rate Card'!$B$17+'Rate Card'!$B$18)) | J11: =MAX('Rate Card'!$B$19,('Rate Card'!$B$8+$A11*'Rate Card'!$E$8+$B11*'Rate Card'!$F$8)*(1+'Rate Card'!$B$17+'Rate Card'!$B$18)) | K11: =MAX('Rate Card'!$B$19,('Rate Card'!$B$8+$A11*'Rate Card'!$G$8+$B11*'Rate Card'!$H$8)*(1+'Rate Card'!$B$17+'Rate Card'!$B$18)) | L11: =MAX('Rate Card'!$B$19,('Rate Card'!$B$9+$A11*'Rate Card'!$C$9+$B11*'Rate Card'!$D$9)*(1+'Rate Card'!$B$17+'Rate Card'!$B$18)) | M11: =MAX('Rate Card'!$B$19,('Rate Card'!$B$9+$A11*'Rate Card'!$E$9+$B11*'Rate Card'!$F$9)*(1+'Rate Card'!$B$17+'Rate Card'!$B$18)) | N11: =MAX('Rate Card'!$B$19,('Rate Card'!$B$9+$A11*'Rate Card'!$G$9+$B11*'Rate Card'!$H$9)*(1+'Rate Card'!$B$17+'Rate Card'!$B$18)) | O11: =MAX('Rate Card'!$B$19,('Rate Card'!$B$10+$A11*'Rate Card'!$C$10+$B11*'Rate Card'!$D$10)*(1+'Rate Card'!$B$17+'Rate Card'!$B$18)) | P11: =MAX('Rate Card'!$B$19,('Rate Card'!$B$10+$A11*'Rate Card'!$E$10+$B11*'Rate Card'!$F$10)*(1+'Rate Card'!$B$17+'Rate Card'!$B$18)) | Q11: =MAX('Rate Card'!$B$19,('Rate Card'!$B$10+$A11*'Rate Card'!$G$10+$B11*'Rate Card'!$H$10)*(1+'Rate Card'!$B$17+'Rate Card'!$B$18))
A12: 20 | B12: =ROUND($A12*'Rate Card'!$B$22,0) | C12: =MAX('Rate Card'!$B$19,('Rate Card'!$B$6+$A12*'Rate Card'!$C$6+$B12*'Rate Card'!$D$6)*(1+'Rate Card'!$B$17+'Rate Card'!$B$18)) | D12: =MAX('Rate Card'!$B$19,('Rate Card'!$B$6+$A12*'Rate Card'!$E$6+$B12*'Rate Card'!$F$6)*(1+'Rate Card'!$B$17+'Rate Card'!$B$18)) | E12: =MAX('Rate Card'!$B$19,('Rate Card'!$B$6+$A12*'Rate Card'!$G$6+$B12*'Rate Card'!$H$6)*(1+'Rate Card'!$B$17+'Rate Card'!$B$18)) | F12: =MAX('Rate Card'!$B$19,('Rate Card'!$B$7+$A12*'Rate Card'!$C$7+$B12*'Rate Card'!$D$7)*(1+'Rate Card'!$B$17+'Rate Card'!$B$18)) | G12: =MAX('Rate Card'!$B$19,('Rate Card'!$B$7+$A12*'Rate Card'!$E$7+$B12*'Rate Card'!$F$7)*(1+'Rate Card'!$B$17+'Rate Card'!$B$18)) | H12: =MAX('Rate Card'!$B$19,('Rate Card'!$B$7+$A12*'Rate Card'!$G$7+$B12*'Rate Card'!$H$7)*(1+'Rate Card'!$B$17+'Rate Card'!$B$18)) | I12: =MAX('Rate Card'!$B$19,('Rate Card'!$B$8+$A12*'Rate Card'!$C$8+$B12*'Rate Card'!$D$8)*(1+'Rate Card'!$B$17+'Rate Card'!$B$18)) | J12: =MAX('Rate Card'!$B$19,('Rate Card'!$B$8+$A12*'Rate Card'!$E$8+$B12*'Rate Card'!$F$8)*(1+'Rate Card'!$B$17+'Rate Card'!$B$18)) | K12: =MAX('Rate Card'!$B$19,('Rate Card'!$B$8+$A12*'Rate Card'!$G$8+$B12*'Rate Card'!$H$8)*(1+'Rate Card'!$B$17+'Rate Card'!$B$18)) | L12: =MAX('Rate Card'!$B$19,('Rate Card'!$B$9+$A12*'Rate Card'!$C$9+$B12*'Rate Card'!$D$9)*(1+'Rate Card'!$B$17+'Rate Card'!$B$18)) | M12: =MAX('Rate Card'!$B$19,('Rate Card'!$B$9+$A12*'Rate Card'!$E$9+$B12*'Rate Card'!$F$9)*(1+'Rate Card'!$B$17+'Rate Card'!$B$18)) | N12: =MAX('Rate Card'!$B$19,('Rate Card'!$B$9+$A12*'Rate Card'!$G$9+$B12*'Rate Card'!$H$9)*(1+'Rate Card'!$B$17+'Rate Card'!$B$18)) | O12: =MAX('Rate Card'!$B$19,('Rate Card'!$B$10+$A12*'Rate Card'!$C$10+$B12*'Rate Card'!$D$10)*(1+'Rate Card'!$B$17+'Rate Card'!$B$18)) | P12: =MAX('Rate Card'!$B$19,('Rate Card'!$B$10+$A12*'Rate Card'!$E$10+$B12*'Rate Card'!$F$10)*(1+'Rate Card'!$B$17+'Rate Card'!$B$18)) | Q12: =MAX('Rate Card'!$B$19,('Rate Card'!$B$10+$A12*'Rate Card'!$G$10+$B12*'Rate Card'!$H$10)*(1+'Rate Card'!$B$17+'Rate Card'!$B$18))
A13: 22 | B13: =ROUND($A13*'Rate Card'!$B$22,0) | C13: =MAX('Rate Card'!$B$19,('Rate Card'!$B$6+$A13*'Rate Card'!$C$6+$B13*'Rate Card'!$D$6)*(1+'Rate Card'!$B$17+'Rate Card'!$B$18)) | D13: =MAX('Rate Card'!$B$19,('Rate Card'!$B$6+$A13*'Rate Card'!$E$6+$B13*'Rate Card'!$F$6)*(1+'Rate Card'!$B$17+'Rate Card'!$B$18)) | E13: =MAX('Rate Card'!$B$19,('Rate Card'!$B$6+$A13*'Rate Card'!$G$6+$B13*'Rate Card'!$H$6)*(1+'Rate Card'!$B$17+'Rate Card'!$B$18)) | F13: =MAX('Rate Card'!$B$19,('Rate Card'!$B$7+$A13*'Rate Card'!$C$7+$B13*'Rate Card'!$D$7)*(1+'Rate Card'!$B$17+'Rate Card'!$B$18)) | G13: =MAX('Rate Card'!$B$19,('Rate Card'!$B$7+$A13*'Rate Card'!$E$7+$B13*'Rate Card'!$F$7)*(1+'Rate Card'!$B$17+'Rate Card'!$B$18)) | H13: =MAX('Rate Card'!$B$19,('Rate Card'!$B$7+$A13*'Rate Card'!$G$7+$B13*'Rate Card'!$H$7)*(1+'Rate Card'!$B$17+'Rate Card'!$B$18)) | I13: =MAX('Rate Card'!$B$19,('Rate Card'!$B$8+$A13*'Rate Card'!$C$8+$B13*'Rate Card'!$D$8)*(1+'Rate Card'!$B$17+'Rate Card'!$B$18)) | J13: =MAX('Rate Card'!$B$19,('Rate Card'!$B$8+$A13*'Rate Card'!$E$8+$B13*'Rate Card'!$F$8)*(1+'Rate Card'!$B$17+'Rate Card'!$B$18)) | K13: =MAX('Rate Card'!$B$19,('Rate Card'!$B$8+$A13*'Rate Card'!$G$8+$B13*'Rate Card'!$H$8)*(1+'Rate Card'!$B$17+'Rate Card'!$B$18)) | L13: =MAX('Rate Card'!$B$19,('Rate Card'!$B$9+$A13*'Rate Card'!$C$9+$B13*'Rate Card'!$D$9)*(1+'Rate Card'!$B$17+'Rate Card'!$B$18)) | M13: =MAX('Rate Card'!$B$19,('Rate Card'!$B$9+$A13*'Rate Card'!$E$9+$B13*'Rate Card'!$F$9)*(1+'Rate Card'!$B$17+'Rate Card'!$B$18)) | N13: =MAX('Rate Card'!$B$19,('Rate Card'!$B$9+$A13*'Rate Card'!$G$9+$B13*'Rate Card'!$H$9)*(1+'Rate Card'!$B$17+'Rate Card'!$B$18)) | O13: =MAX('Rate Card'!$B$19,('Rate Card'!$B$10+$A13*'Rate Card'!$C$10+$B13*'Rate Card'!$D$10)*(1+'Rate Card'!$B$17+'Rate Card'!$B$18)) | P13: =MAX('Rate Card'!$B$19,('Rate Card'!$B$10+$A13*'Rate Card'!$E$10+$B13*'Rate Card'!$F$10)*(1+'Rate Card'!$B$17+'Rate Card'!$B$18)) | Q13: =MAX('Rate Card'!$B$19,('Rate Card'!$B$10+$A13*'Rate Card'!$G$10+$B13*'Rate Card'!$H$10)*(1+'Rate Card'!$B$17+'Rate Card'!$B$18))
A14: 24 | B14: =ROUND($A14*'Rate Card'!$B$22,0) | C14: =MAX('Rate Card'!$B$19,('Rate Card'!$B$6+$A14*'Rate Card'!$C$6+$B14*'Rate Card'!$D$6)*(1+'Rate Card'!$B$17+'Rate Card'!$B$18)) | D14: =MAX('Rate Card'!$B$19,('Rate Card'!$B$6+$A14*'Rate Card'!$E$6+$B14*'Rate Card'!$F$6)*(1+'Rate Card'!$B$17+'Rate Card'!$B$18)) | E14: =MAX('Rate Card'!$B$19,('Rate Card'!$B$6+$A14*'Rate Card'!$G$6+$B14*'Rate Card'!$H$6)*(1+'Rate Card'!$B$17+'Rate Card'!$B$18)) | F14: =MAX('Rate Card'!$B$19,('Rate Card'!$B$7+$A14*'Rate Card'!$C$7+$B14*'Rate Card'!$D$7)*(1+'Rate Card'!$B$17+'Rate Card'!$B$18)) | G14: =MAX('Rate Card'!$B$19,('Rate Card'!$B$7+$A14*'Rate Card'!$E$7+$B14*'Rate Card'!$F$7)*(1+'Rate Card'!$B$17+'Rate Card'!$B$18)) | H14: =MAX('Rate Card'!$B$19,('Rate Card'!$B$7+$A14*'Rate Card'!$G$7+$B14*'Rate Card'!$H$7)*(1+'Rate Card'!$B$17+'Rate Card'!$B$18)) | I14: =MAX('Rate Card'!$B$19,('Rate Card'!$B$8+$A14*'Rate Card'!$C$8+$B14*'Rate Card'!$D$8)*(1+'Rate Card'!$B$17+'Rate Card'!$B$18)) | J14: =MAX('Rate Card'!$B$19,('Rate Card'!$B$8+$A14*'Rate Card'!$E$8+$B14*'Rate Card'!$F$8)*(1+'Rate Card'!$B$17+'Rate Card'!$B$18)) | K14: =MAX('Rate Card'!$B$19,('Rate Card'!$B$8+$A14*'Rate Card'!$G$8+$B14*'Rate Card'!$H$8)*(1+'Rate Card'!$B$17+'Rate Card'!$B$18)) | L14: =MAX('Rate Card'!$B$19,('Rate Card'!$B$9+$A14*'Rate Card'!$C$9+$B14*'Rate Card'!$D$9)*(1+'Rate Card'!$B$17+'Rate Card'!$B$18)) | M14: =MAX('Rate Card'!$B$19,('Rate Card'!$B$9+$A14*'Rate Card'!$E$9+$B14*'Rate Card'!$F$9)*(1+'Rate Card'!$B$17+'Rate Card'!$B$18)) | N14: =MAX('Rate Card'!$B$19,('Rate Card'!$B$9+$A14*'Rate Card'!$G$9+$B14*'Rate Card'!$H$9)*(1+'Rate Card'!$B$17+'Rate Card'!$B$18)) | O14: =MAX('Rate Card'!$B$19,('Rate Card'!$B$10+$A14*'Rate Card'!$C$10+$B14*'Rate Card'!$D$10)*(1+'Rate Card'!$B$17+'Rate Card'!$B$18)) | P14: =MAX('Rate Card'!$B$19,('Rate Card'!$B$10+$A14*'Rate Card'!$E$10+$B14*'Rate Card'!$F$10)*(1+'Rate Card'!$B$17+'Rate Card'!$B$18)) | Q14: =MAX('Rate Card'!$B$19,('Rate Card'!$B$10+$A14*'Rate Card'!$G$10+$B14*'Rate Card'!$H$10)*(1+'Rate Card'!$B$17+'Rate Card'!$B$18))
A15: 26 | B15: =ROUND($A15*'Rate Card'!$B$22,0) | C15: =MAX('Rate Card'!$B$19,('Rate Card'!$B$6+$A15*'Rate Card'!$C$6+$B15*'Rate Card'!$D$6)*(1+'Rate Card'!$B$17+'Rate Card'!$B$18)) | D15: =MAX('Rate Card'!$B$19,('Rate Card'!$B$6+$A15*'Rate Card'!$E$6+$B15*'Rate Card'!$F$6)*(1+'Rate Card'!$B$17+'Rate Card'!$B$18)) | E15: =MAX('Rate Card'!$B$19,('Rate Card'!$B$6+$A15*'Rate Card'!$G$6+$B15*'Rate Card'!$H$6)*(1+'Rate Card'!$B$17+'Rate Card'!$B$18)) | F15: =MAX('Rate Card'!$B$19,('Rate Card'!$B$7+$A15*'Rate Card'!$C$7+$B15*'Rate Card'!$D$7)*(1+'Rate Card'!$B$17+'Rate Card'!$B$18)) | G15: =MAX('Rate Card'!$B$19,('Rate Card'!$B$7+$A15*'Rate Card'!$E$7+$B15*'Rate Card'!$F$7)*(1+'Rate Card'!$B$17+'Rate Card'!$B$18)) | H15: =MAX('Rate Card'!$B$19,('Rate Card'!$B$7+$A15*'Rate Card'!$G$7+$B15*'Rate Card'!$H$7)*(1+'Rate Card'!$B$17+'Rate Card'!$B$18)) | I15: =MAX('Rate Card'!$B$19,('Rate Card'!$B$8+$A15*'Rate Card'!$C$8+$B15*'Rate Card'!$D$8)*(1+'Rate Card'!$B$17+'Rate Card'!$B$18)) | J15: =MAX('Rate Card'!$B$19,('Rate Card'!$B$8+$A15*'Rate Card'!$E$8+$B15*'Rate Card'!$F$8)*(1+'Rate Card'!$B$17+'Rate Card'!$B$18)) | K15: =MAX('Rate Card'!$B$19,('Rate Card'!$B$8+$A15*'Rate Card'!$G$8+$B15*'Rate Card'!$H$8)*(1+'Rate Card'!$B$17+'Rate Card'!$B$18)) | L15: =MAX('Rate Card'!$B$19,('Rate Card'!$B$9+$A15*'Rate Card'!$C$9+$B15*'Rate Card'!$D$9)*(1+'Rate Card'!$B$17+'Rate Card'!$B$18)) | M15: =MAX('Rate Card'!$B$19,('Rate Card'!$B$9+$A15*'Rate Card'!$E$9+$B15*'Rate Card'!$F$9)*(1+'Rate Card'!$B$17+'Rate Card'!$B$18)) | N15: =MAX('Rate Card'!$B$19,('Rate Card'!$B$9+$A15*'Rate Card'!$G$9+$B15*'Rate Card'!$H$9)*(1+'Rate Card'!$B$17+'Rate Card'!$B$18)) | O15: =MAX('Rate Card'!$B$19,('Rate Card'!$B$10+$A15*'Rate Card'!$C$10+$B15*'Rate Card'!$D$10)*(1+'Rate Card'!$B$17+'Rate Card'!$B$18)) | P15: =MAX('Rate Card'!$B$19,('Rate Card'!$B$10+$A15*'Rate Card'!$E$10+$B15*'Rate Card'!$F$10)*(1+'Rate Card'!$B$17+'Rate Card'!$B$18)) | Q15: =MAX('Rate Card'!$B$19,('Rate Card'!$B$10+$A15*'Rate Card'!$G$10+$B15*'Rate Card'!$H$10)*(1+'Rate Card'!$B$17+'Rate Card'!$B$18))
A16: 28 | B16: =ROUND($A16*'Rate Card'!$B$22,0) | C16: =MAX('Rate Card'!$B$19,('Rate Card'!$B$6+$A16*'Rate Card'!$C$6+$B16*'Rate Card'!$D$6)*(1+'Rate Card'!$B$17+'Rate Card'!$B$18)) | D16: =MAX('Rate Card'!$B$19,('Rate Card'!$B$6+$A16*'Rate Card'!$E$6+$B16*'Rate Card'!$F$6)*(1+'Rate Card'!$B$17+'Rate Card'!$B$18)) | E16: =MAX('Rate Card'!$B$19,('Rate Card'!$B$6+$A16*'Rate Card'!$G$6+$B16*'Rate Card'!$H$6)*(1+'Rate Card'!$B$17+'Rate Card'!$B$18)) | F16: =MAX('Rate Card'!$B$19,('Rate Card'!$B$7+$A16*'Rate Card'!$C$7+$B16*'Rate Card'!$D$7)*(1+'Rate Card'!$B$17+'Rate Card'!$B$18)) | G16: =MAX('Rate Card'!$B$19,('Rate Card'!$B$7+$A16*'Rate Card'!$E$7+$B16*'Rate Card'!$F$7)*(1+'Rate Card'!$B$17+'Rate Card'!$B$18)) | H16: =MAX('Rate Card'!$B$19,('Rate Card'!$B$7+$A16*'Rate Card'!$G$7+$B16*'Rate Card'!$H$7)*(1+'Rate Card'!$B$17+'Rate Card'!$B$18)) | I16: =MAX('Rate Card'!$B$19,('Rate Card'!$B$8+$A16*'Rate Card'!$C$8+$B16*'Rate Card'!$D$8)*(1+'Rate Card'!$B$17+'Rate Card'!$B$18)) | J16: =MAX('Rate Card'!$B$19,('Rate Card'!$B$8+$A16*'Rate Card'!$E$8+$B16*'Rate Card'!$F$8)*(1+'Rate Card'!$B$17+'Rate Card'!$B$18)) | K16: =MAX('Rate Card'!$B$19,('Rate Card'!$B$8+$A16*'Rate Card'!$G$8+$B16*'Rate Card'!$H$8)*(1+'Rate Card'!$B$17+'Rate Card'!$B$18)) | L16: =MAX('Rate Card'!$B$19,('Rate Card'!$B$9+$A16*'Rate Card'!$C$9+$B16*'Rate Card'!$D$9)*(1+'Rate Card'!$B$17+'Rate Card'!$B$18)) | M16: =MAX('Rate Card'!$B$19,('Rate Card'!$B$9+$A16*'Rate Card'!$E$9+$B16*'Rate Card'!$F$9)*(1+'Rate Card'!$B$17+'Rate Card'!$B$18)) | N16: =MAX('Rate Card'!$B$19,('Rate Card'!$B$9+$A16*'Rate Card'!$G$9+$B16*'Rate Card'!$H$9)*(1+'Rate Card'!$B$17+'Rate Card'!$B$18)) | O16: =MAX('Rate Card'!$B$19,('Rate Card'!$B$10+$A16*'Rate Card'!$C$10+$B16*'Rate Card'!$D$10)*(1+'Rate Card'!$B$17+'Rate Card'!$B$18)) | P16: =MAX('Rate Card'!$B$19,('Rate Card'!$B$10+$A16*'Rate Card'!$E$10+$B16*'Rate Card'!$F$10)*(1+'Rate Card'!$B$17+'Rate Card'!$B$18)) | Q16: =MAX('Rate Card'!$B$19,('Rate Card'!$B$10+$A16*'Rate Card'!$G$10+$B16*'Rate Card'!$H$10)*(1+'Rate Card'!$B$17+'Rate Card'!$B$18))
A17: 30 | B17: =ROUND($A17*'Rate Card'!$B$22,0) | C17: =MAX('Rate Card'!$B$19,('Rate Card'!$B$6+$A17*'Rate Card'!$C$6+$B17*'Rate Card'!$D$6)*(1+'Rate Card'!$B$17+'Rate Card'!$B$18)) | D17: =MAX('Rate Card'!$B$19,('Rate Card'!$B$6+$A17*'Rate Card'!$E$6+$B17*'Rate Card'!$F$6)*(1+'Rate Card'!$B$17+'Rate Card'!$B$18)) | E17: =MAX('Rate Card'!$B$19,('Rate Card'!$B$6+$A17*'Rate Card'!$G$6+$B17*'Rate Card'!$H$6)*(1+'Rate Card'!$B$17+'Rate Card'!$B$18)) | F17: =MAX('Rate Card'!$B$19,('Rate Card'!$B$7+$A17*'Rate Card'!$C$7+$B17*'Rate Card'!$D$7)*(1+'Rate Card'!$B$17+'Rate Card'!$B$18)) | G17: =MAX('Rate Card'!$B$19,('Rate Card'!$B$7+$A17*'Rate Card'!$E$7+$B17*'Rate Card'!$F$7)*(1+'Rate Card'!$B$17+'Rate Card'!$B$18)) | H17: =MAX('Rate Card'!$B$19,('Rate Card'!$B$7+$A17*'Rate Card'!$G$7+$B17*'Rate Card'!$H$7)*(1+'Rate Card'!$B$17+'Rate Card'!$B$18)) | I17: =MAX('Rate Card'!$B$19,('Rate Card'!$B$8+$A17*'Rate Card'!$C$8+$B17*'Rate Card'!$D$8)*(1+'Rate Card'!$B$17+'Rate Card'!$B$18)) | J17: =MAX('Rate Card'!$B$19,('Rate Card'!$B$8+$A17*'Rate Card'!$E$8+$B17*'Rate Card'!$F$8)*(1+'Rate Card'!$B$17+'Rate Card'!$B$18)) | K17: =MAX('Rate Card'!$B$19,('Rate Card'!$B$8+$A17*'Rate Card'!$G$8+$B17*'Rate Card'!$H$8)*(1+'Rate Card'!$B$17+'Rate Card'!$B$18)) | L17: =MAX('Rate Card'!$B$19,('Rate Card'!$B$9+$A17*'Rate Card'!$C$9+$B17*'Rate Card'!$D$9)*(1+'Rate Card'!$B$17+'Rate Card'!$B$18)) | M17: =MAX('Rate Card'!$B$19,('Rate Card'!$B$9+$A17*'Rate Card'!$E$9+$B17*'Rate Card'!$F$9)*(1+'Rate Card'!$B$17+'Rate Card'!$B$18)) | N17: =MAX('Rate Card'!$B$19,('Rate Card'!$B$9+$A17*'Rate Card'!$G$9+$B17*'Rate Card'!$H$9)*(1+'Rate Card'!$B$17+'Rate Card'!$B$18)) | O17: =MAX('Rate Card'!$B$19,('Rate Card'!$B$10+$A17*'Rate Card'!$C$10+$B17*'Rate Card'!$D$10)*(1+'Rate Card'!$B$17+'Rate Card'!$B$18)) | P17: =MAX('Rate Card'!$B$19,('Rate Card'!$B$10+$A17*'Rate Card'!$E$10+$B17*'Rate Card'!$F$10)*(1+'Rate Card'!$B$17+'Rate Card'!$B$18)) | Q17: =MAX('Rate Card'!$B$19,('Rate Card'!$B$10+$A17*'Rate Card'!$G$10+$B17*'Rate Card'!$H$10)*(1+'Rate Card'!$B$17+'Rate Card'!$B$18))
... A32: 60 | B32: =ROUND($A32*'Rate Card'!$B$22,0) | C32: =MAX('Rate Card'!$B$19,('Rate Card'!$B$6+$A32*'Rate Card'!$C$6+$B32*'Rate Card'!$D$6)*(1+'Rate Card'!$B$17+'Rate Card'!$B$18)) | D32: =MAX('Rate Card'!$B$19,('Rate Card'!$B$6+$A32*'Rate Card'!$E$6+$B32*'Rate Card'!$F$6)*(1+'Rate Card'!$B$17+'Rate Card'!$B$18)) | E32: =MAX('Rate Card'!$B$19,('Rate Card'!$B$6+$A32*'Rate Card'!$G$6+$B32*'Rate Card'!$H$6)*(1+'Rate Card'!$B$17+'Rate Card'!$B$18)) | F32: =MAX('Rate Card'!$B$19,('Rate Card'!$B$7+$A32*'Rate Card'!$C$7+$B32*'Rate Card'!$D$7)*(1+'Rate Card'!$B$17+'Rate Card'!$B$18)) | G32: =MAX('Rate Card'!$B$19,('Rate Card'!$B$7+$A32*'Rate Card'!$E$7+$B32*'Rate Card'!$F$7)*(1+'Rate Card'!$B$17+'Rate Card'!$B$18)) | H32: =MAX('Rate Card'!$B$19,('Rate Card'!$B$7+$A32*'Rate Card'!$G$7+$B32*'Rate Card'!$H$7)*(1+'Rate Card'!$B$17+'Rate Card'!$B$18)) | I32: =MAX('Rate Card'!$B$19,('Rate Card'!$B$8+$A32*'Rate Card'!$C$8+$B32*'Rate Card'!$D$8)*(1+'Rate Card'!$B$17+'Rate Card'!$B$18)) | J32: =MAX('Rate Card'!$B$19,('Rate Card'!$B$8+$A32*'Rate Card'!$E$8+$B32*'Rate Card'!$F$8)*(1+'Rate Card'!$B$17+'Rate Card'!$B$18)) | K32: =MAX('Rate Card'!$B$19,('Rate Card'!$B$8+$A32*'Rate Card'!$G$8+$B32*'Rate Card'!$H$8)*(1+'Rate Card'!$B$17+'Rate Card'!$B$18)) | L32: =MAX('Rate Card'!$B$19,('Rate Card'!$B$9+$A32*'Rate Card'!$C$9+$B32*'Rate Card'!$D$9)*(1+'Rate Card'!$B$17+'Rate Card'!$B$18)) | M32: =MAX('Rate Card'!$B$19,('Rate Card'!$B$9+$A32*'Rate Card'!$E$9+$B32*'Rate Card'!$F$9)*(1+'Rate Card'!$B$17+'Rate Card'!$B$18)) | N32: =MAX('Rate Card'!$B$19,('Rate Card'!$B$9+$A32*'Rate Card'!$G$9+$B32*'Rate Card'!$H$9)*(1+'Rate Card'!$B$17+'Rate Card'!$B$18)) | O32: =MAX('Rate Card'!$B$19,('Rate Card'!$B$10+$A32*'Rate Card'!$C$10+$B32*'Rate Card'!$D$10)*(1+'Rate Card'!$B$17+'Rate Card'!$B$18)) | P32: =MAX('Rate Card'!$B$19,('Rate Card'!$B$10+$A32*'Rate Card'!$E$10+$B32*'Rate Card'!$F$10)*(1+'Rate Card'!$B$17+'Rate Card'!$B$18)) | Q32: =MAX('Rate Card'!$B$19,('Rate Card'!$B$10+$A32*'Rate Card'!$G$10+$B32*'Rate Card'!$H$10)*(1+'Rate Card'!$B$17+'Rate Card'!$B$18))
